Traceback (most recent call last):
  File "/Users/johnmyers/miniconda3/envs/python-2023-12/lib/python3.10/site-packages/jupyter_cache/executors/utils.py", line 58, in single_nb_execution
    executenb(
  File "/Users/johnmyers/miniconda3/envs/python-2023-12/lib/python3.10/site-packages/nbclient/client.py", line 1305, in execute
    return NotebookClient(nb=nb, resources=resources, km=km, **kwargs).execute()
  File "/Users/johnmyers/miniconda3/envs/python-2023-12/lib/python3.10/site-packages/jupyter_core/utils/__init__.py", line 173, in wrapped
    return loop.run_until_complete(inner)
  File "/Users/johnmyers/miniconda3/envs/python-2023-12/lib/python3.10/asyncio/base_events.py", line 649, in run_until_complete
    return future.result()
  File "/Users/johnmyers/miniconda3/envs/python-2023-12/lib/python3.10/site-packages/nbclient/client.py", line 705, in async_execute
    await self.async_execute_cell(
  File "/Users/johnmyers/miniconda3/envs/python-2023-12/lib/python3.10/site-packages/nbclient/client.py", line 1058, in async_execute_cell
    await self._check_raise_for_error(cell, cell_index, exec_reply)
  File "/Users/johnmyers/miniconda3/envs/python-2023-12/lib/python3.10/site-packages/nbclient/client.py", line 914, in _check_raise_for_error
    raise CellExecutionError.from_cell_and_msg(cell, exec_reply_content)
nbclient.exceptions.CellExecutionError: An error occurred while executing the following cell:
------------------
# SGD parameters
num_epochs = 1
batch_size = 1
random_state = 42
gd_parameters = {'lr': [1e-1, 1e-1, 3e-2, 3e-2],
               'max_steps': [10, 100, 80, 160]}
parameters_list = []
objectives_list = []

# run SGD
for i in range(4):
    parameters = {'theta': torch.tensor([1.5, 1.5], requires_grad=True)}
    gd_parameters_slice = {key: value[i] for key, value in gd_parameters.items()}
    running_parameters, running_objectives = SGD(parameters=parameters,
                                                 dataset=dataset,
                                                 J=J,
                                                 tracking='gd_step',
                                                 num_epochs=1,
                                                 batch_size=batch_size,
                                                 random_state=random_state,
                                                 **gd_parameters_slice)
    parameters_list.append(running_parameters)
    objectives_list.append(running_objectives)

# plot the objective function
_, axes = plt.subplots(nrows=2, ncols=2, figsize=(9, 6), sharey=True)

for i in range(4):
    idx = axes_idx[i]
    objectives = objectives_list[i]
    gd_parameters_slice = {key: value[i] for key, value in gd_parameters.items()}
    lr = gd_parameters_slice['lr']
    axes[idx].plot(range(len(objectives)), objectives)
    axes[idx].set_xlabel('gradient steps')
    axes[idx].set_ylabel('objective')
    axes[idx].set_title(fr'$\alpha={lr}$, $\gamma=0$')

plt.tight_layout()
------------------


[0;31m---------------------------------------------------------------------------[0m
[0;31mNameError[0m                                 Traceback (most recent call last)
Cell [0;32mIn[17], line 29[0m
[1;32m     26[0m _, axes [38;5;241m=[39m plt[38;5;241m.[39msubplots(nrows[38;5;241m=[39m[38;5;241m2[39m, ncols[38;5;241m=[39m[38;5;241m2[39m, figsize[38;5;241m=[39m([38;5;241m9[39m, [38;5;241m6[39m), sharey[38;5;241m=[39m[38;5;28;01mTrue[39;00m)
[1;32m     28[0m [38;5;28;01mfor[39;00m i [38;5;129;01min[39;00m [38;5;28mrange[39m([38;5;241m4[39m):
[0;32m---> 29[0m     idx [38;5;241m=[39m [43maxes_idx[49m[i]
[1;32m     30[0m     objectives [38;5;241m=[39m objectives_list[i]
[1;32m     31[0m     gd_parameters_slice [38;5;241m=[39m {key: value[i] [38;5;28;01mfor[39;00m key, value [38;5;129;01min[39;00m gd_parameters[38;5;241m.[39mitems()}

[0;31mNameError[0m: name 'axes_idx' is not defined

