Traceback (most recent call last):
  File "/Users/johnmyers/miniconda3/envs/python-2023-12/lib/python3.10/site-packages/jupyter_cache/executors/utils.py", line 58, in single_nb_execution
    executenb(
  File "/Users/johnmyers/miniconda3/envs/python-2023-12/lib/python3.10/site-packages/nbclient/client.py", line 1305, in execute
    return NotebookClient(nb=nb, resources=resources, km=km, **kwargs).execute()
  File "/Users/johnmyers/miniconda3/envs/python-2023-12/lib/python3.10/site-packages/jupyter_core/utils/__init__.py", line 173, in wrapped
    return loop.run_until_complete(inner)
  File "/Users/johnmyers/miniconda3/envs/python-2023-12/lib/python3.10/asyncio/base_events.py", line 649, in run_until_complete
    return future.result()
  File "/Users/johnmyers/miniconda3/envs/python-2023-12/lib/python3.10/site-packages/nbclient/client.py", line 705, in async_execute
    await self.async_execute_cell(
  File "/Users/johnmyers/miniconda3/envs/python-2023-12/lib/python3.10/site-packages/nbclient/client.py", line 1058, in async_execute_cell
    await self._check_raise_for_error(cell, cell_index, exec_reply)
  File "/Users/johnmyers/miniconda3/envs/python-2023-12/lib/python3.10/site-packages/nbclient/client.py", line 914, in _check_raise_for_error
    raise CellExecutionError.from_cell_and_msg(cell, exec_reply_content)
nbclient.exceptions.CellExecutionError: An error occurred while executing the following cell:
------------------
_, axes = plt.subplots(nrows=1, ncols=2, figsize=(9, 4.5))

for i in range(2):
    running_parameters = parameters_list[i]['theta']
    gd_parameters_slice = {key: value[i] for key, value in gd_parameters.items()}
    lr = gd_parameters_slice['lr']
    num_epochs = gd_parameters_slice['num_epochs']
    axes[i].contour(grid_1, grid_2, z, levels=torch.arange(start=0, end=10, step=0.5), colors=blue, alpha=0.5)
    axes[i].plot(running_parameters[:, 0], running_parameters[:, 1], color=magenta)
    axes[i].scatter(running_parameters[:, 0], running_parameters[:, 1], s=30, color=magenta, zorder=2)
    axes[i].scatter(running_parameters[0, 0], running_parameters[0, 1], s=100, color=magenta, zorder=2)
    axes[i].set_title(fr'$\alpha={lr}$, $\gamma=0$, gradient steps$={num_epochs}$')
    axes[i].set_xlabel(r'$\theta_1$')
    axes[i].set_ylabel(r'$\theta_2$')

plt.tight_layout()
------------------


[0;31m---------------------------------------------------------------------------[0m
[0;31mNameError[0m                                 Traceback (most recent call last)
Cell [0;32mIn[16], line 4[0m
[1;32m      1[0m _, axes [38;5;241m=[39m plt[38;5;241m.[39msubplots(nrows[38;5;241m=[39m[38;5;241m1[39m, ncols[38;5;241m=[39m[38;5;241m2[39m, figsize[38;5;241m=[39m([38;5;241m9[39m, [38;5;241m4.5[39m))
[1;32m      3[0m [38;5;28;01mfor[39;00m i [38;5;129;01min[39;00m [38;5;28mrange[39m([38;5;241m2[39m):
[0;32m----> 4[0m     running_parameters [38;5;241m=[39m [43mparameters_list[49m[i][[38;5;124m'[39m[38;5;124mtheta[39m[38;5;124m'[39m]
[1;32m      5[0m     gd_parameters_slice [38;5;241m=[39m {key: value[i] [38;5;28;01mfor[39;00m key, value [38;5;129;01min[39;00m gd_parameters[38;5;241m.[39mitems()}
[1;32m      6[0m     lr [38;5;241m=[39m gd_parameters_slice[[38;5;124m'[39m[38;5;124mlr[39m[38;5;124m'[39m]

[0;31mNameError[0m: name 'parameters_list' is not defined

