Traceback (most recent call last):
  File "/Users/johnmyers/opt/anaconda3/envs/python-2023-08-v2/lib/python3.11/site-packages/jupyter_cache/executors/utils.py", line 58, in single_nb_execution
    executenb(
  File "/Users/johnmyers/opt/anaconda3/envs/python-2023-08-v2/lib/python3.11/site-packages/nbclient/client.py", line 1305, in execute
    return NotebookClient(nb=nb, resources=resources, km=km, **kwargs).execute()
           ^^^^^^^^^^^^^^^^^^^^^^^^^^^^^^^^^^^^^^^^^^^^^^^^^^^^^^^^^^^^^^^^^^^^^
  File "/Users/johnmyers/opt/anaconda3/envs/python-2023-08-v2/lib/python3.11/site-packages/jupyter_core/utils/__init__.py", line 166, in wrapped
    return loop.run_until_complete(inner)
           ^^^^^^^^^^^^^^^^^^^^^^^^^^^^^^
  File "/Users/johnmyers/opt/anaconda3/envs/python-2023-08-v2/lib/python3.11/asyncio/base_events.py", line 653, in run_until_complete
    return future.result()
           ^^^^^^^^^^^^^^^
  File "/Users/johnmyers/opt/anaconda3/envs/python-2023-08-v2/lib/python3.11/site-packages/nbclient/client.py", line 705, in async_execute
    await self.async_execute_cell(
  File "/Users/johnmyers/opt/anaconda3/envs/python-2023-08-v2/lib/python3.11/site-packages/nbclient/client.py", line 1058, in async_execute_cell
    await self._check_raise_for_error(cell, cell_index, exec_reply)
  File "/Users/johnmyers/opt/anaconda3/envs/python-2023-08-v2/lib/python3.11/site-packages/nbclient/client.py", line 914, in _check_raise_for_error
    raise CellExecutionError.from_cell_and_msg(cell, exec_reply_content)
nbclient.exceptions.CellExecutionError: An error occurred while executing the following cell:
------------------
import scipy as sp
from itertools import product

np.random.seed(42)
sigma = np.sqrt(lr.scale)

_, axes = plt.subplots(nrows=2, ncols=2, figsize=(8, 6), sharex=True, sharey=True)
for i, j in product(range(2), range(2)):
    y_gen = sp.stats.norm(loc=y_hat, scale=sigma).rvs(2930)
    df_gen = pd.DataFrame({'area': df['area'], 'price': y_gen})
    df_gen.plot(kind='scatter', x='area', y='price', alpha=0.15, ax=axes[i, j])
    axes[i, j].plot(grid, beta_0 + beta_1 * grid, color=magenta)
axes[0, 0].set_title(f'generated dataset 1')
axes[0, 1].set_title(f'generated dataset 2')
axes[1, 0].set_title(f'generated dataset 3')
axes[1, 1].set_title(f'generated dataset 4')
plt.tight_layout()
------------------


[0;31m---------------------------------------------------------------------------[0m
[0;31mNameError[0m                                 Traceback (most recent call last)
Cell [0;32mIn[4], line 9[0m
[1;32m      7[0m _, axes [38;5;241m=[39m plt[38;5;241m.[39msubplots(nrows[38;5;241m=[39m[38;5;241m2[39m, ncols[38;5;241m=[39m[38;5;241m2[39m, figsize[38;5;241m=[39m([38;5;241m8[39m, [38;5;241m6[39m), sharex[38;5;241m=[39m[38;5;28;01mTrue[39;00m, sharey[38;5;241m=[39m[38;5;28;01mTrue[39;00m)
[1;32m      8[0m [38;5;28;01mfor[39;00m i, j [38;5;129;01min[39;00m product([38;5;28mrange[39m([38;5;241m2[39m), [38;5;28mrange[39m([38;5;241m2[39m)):
[0;32m----> 9[0m     y_gen [38;5;241m=[39m sp[38;5;241m.[39mstats[38;5;241m.[39mnorm(loc[38;5;241m=[39m[43my_hat[49m, scale[38;5;241m=[39msigma)[38;5;241m.[39mrvs([38;5;241m2930[39m)
[1;32m     10[0m     df_gen [38;5;241m=[39m pd[38;5;241m.[39mDataFrame({[38;5;124m'[39m[38;5;124marea[39m[38;5;124m'[39m: df[[38;5;124m'[39m[38;5;124marea[39m[38;5;124m'[39m], [38;5;124m'[39m[38;5;124mprice[39m[38;5;124m'[39m: y_gen})
[1;32m     11[0m     df_gen[38;5;241m.[39mplot(kind[38;5;241m=[39m[38;5;124m'[39m[38;5;124mscatter[39m[38;5;124m'[39m, x[38;5;241m=[39m[38;5;124m'[39m[38;5;124marea[39m[38;5;124m'[39m, y[38;5;241m=[39m[38;5;124m'[39m[38;5;124mprice[39m[38;5;124m'[39m, alpha[38;5;241m=[39m[38;5;241m0.15[39m, ax[38;5;241m=[39maxes[i, j])

[0;31mNameError[0m: name 'y_hat' is not defined

