Traceback (most recent call last):
  File "/Users/johnmyers/miniconda3/envs/python-2023-12/lib/python3.10/site-packages/jupyter_cache/executors/utils.py", line 58, in single_nb_execution
    executenb(
  File "/Users/johnmyers/miniconda3/envs/python-2023-12/lib/python3.10/site-packages/nbclient/client.py", line 1305, in execute
    return NotebookClient(nb=nb, resources=resources, km=km, **kwargs).execute()
  File "/Users/johnmyers/miniconda3/envs/python-2023-12/lib/python3.10/site-packages/jupyter_core/utils/__init__.py", line 173, in wrapped
    return loop.run_until_complete(inner)
  File "/Users/johnmyers/miniconda3/envs/python-2023-12/lib/python3.10/asyncio/base_events.py", line 649, in run_until_complete
    return future.result()
  File "/Users/johnmyers/miniconda3/envs/python-2023-12/lib/python3.10/site-packages/nbclient/client.py", line 705, in async_execute
    await self.async_execute_cell(
  File "/Users/johnmyers/miniconda3/envs/python-2023-12/lib/python3.10/site-packages/nbclient/client.py", line 1058, in async_execute_cell
    await self._check_raise_for_error(cell, cell_index, exec_reply)
  File "/Users/johnmyers/miniconda3/envs/python-2023-12/lib/python3.10/site-packages/nbclient/client.py", line 914, in _check_raise_for_error
    raise CellExecutionError.from_cell_and_msg(cell, exec_reply_content)
nbclient.exceptions.CellExecutionError: An error occurred while executing the following cell:
------------------
gd_parameters = {'init_parameters': [torch.tensor([0.25, 0.9]),
                                     torch.tensor([0.25, 1]),
                                     torch.tensor([0.75, 1.2]),
                                     torch.tensor([0.5, 0.49])]}
alpha = 1e-2
beta = 0
N = 125

fig, axes = plt.subplots(nrows=2, ncols=2, figsize=(9, 6), sharey=True)

for i, axis in enumerate(axes.flatten()):
    gd_parameters_slice = {key: value[i] for key, value in gd_parameters.items()}
    gd_output = GD(J=J,
                   lr=alpha,
                   num_steps=N,
                   decay_rate=beta,
                   **gd_parameters_slice)
    
    axis.plot(range(len(gd_output.objectives)), gd_output.objectives)
    
    axis.set_xlabel('gradient steps')
    axis.set_ylabel('objective')
    axis.set_title(f'$\\alpha={alpha}$, $\\beta={beta}$, $N={N}$')
fig.suptitle('first runs of gradient descent')
plt.tight_layout()
------------------


[0;31m---------------------------------------------------------------------------[0m
[0;31mAttributeError[0m                            Traceback (most recent call last)
Cell [0;32mIn[11], line 19[0m
[1;32m     12[0m gd_parameters_slice [38;5;241m=[39m {key: value[i] [38;5;28;01mfor[39;00m key, value [38;5;129;01min[39;00m gd_parameters[38;5;241m.[39mitems()}
[1;32m     13[0m gd_output [38;5;241m=[39m GD(J[38;5;241m=[39mJ,
[1;32m     14[0m                lr[38;5;241m=[39malpha,
[1;32m     15[0m                num_steps[38;5;241m=[39mN,
[1;32m     16[0m                decay_rate[38;5;241m=[39mbeta,
[1;32m     17[0m                [38;5;241m*[39m[38;5;241m*[39mgd_parameters_slice)
[0;32m---> 19[0m axis[38;5;241m.[39mplot([38;5;28mrange[39m([38;5;28mlen[39m([43mgd_output[49m[38;5;241;43m.[39;49m[43mobjectives[49m)), gd_output[38;5;241m.[39mobjectives)
[1;32m     21[0m axis[38;5;241m.[39mset_xlabel([38;5;124m'[39m[38;5;124mgradient steps[39m[38;5;124m'[39m)
[1;32m     22[0m axis[38;5;241m.[39mset_ylabel([38;5;124m'[39m[38;5;124mobjective[39m[38;5;124m'[39m)

[0;31mAttributeError[0m: 'GD_output' object has no attribute 'objectives'

