Traceback (most recent call last):
  File "/Users/johnmyers/miniconda3/envs/python-2023-12/lib/python3.10/site-packages/jupyter_cache/executors/utils.py", line 58, in single_nb_execution
    executenb(
  File "/Users/johnmyers/miniconda3/envs/python-2023-12/lib/python3.10/site-packages/nbclient/client.py", line 1305, in execute
    return NotebookClient(nb=nb, resources=resources, km=km, **kwargs).execute()
  File "/Users/johnmyers/miniconda3/envs/python-2023-12/lib/python3.10/site-packages/jupyter_core/utils/__init__.py", line 173, in wrapped
    return loop.run_until_complete(inner)
  File "/Users/johnmyers/miniconda3/envs/python-2023-12/lib/python3.10/asyncio/base_events.py", line 649, in run_until_complete
    return future.result()
  File "/Users/johnmyers/miniconda3/envs/python-2023-12/lib/python3.10/site-packages/nbclient/client.py", line 705, in async_execute
    await self.async_execute_cell(
  File "/Users/johnmyers/miniconda3/envs/python-2023-12/lib/python3.10/site-packages/nbclient/client.py", line 1058, in async_execute_cell
    await self._check_raise_for_error(cell, cell_index, exec_reply)
  File "/Users/johnmyers/miniconda3/envs/python-2023-12/lib/python3.10/site-packages/nbclient/client.py", line 914, in _check_raise_for_error
    raise CellExecutionError.from_cell_and_msg(cell, exec_reply_content)
nbclient.exceptions.CellExecutionError: An error occurred while executing the following cell:
------------------
url = 'https://raw.githubusercontent.com/jmyers7/stats-book-materials/main/data/ch-11-12-data.csv'
data = pd.read_csv(url)
class_0 = data[data['y'] == 0][['x_1', 'x_2']]
class_1 = data[data['y'] == 1][['x_1', 'x_2']]
class_0 = torch.tensor(data=class_0.to_numpy(), dtype=torch.float32)
class_1 = torch.tensor(data=class_1.to_numpy(), dtype=torch.float32)
data = torch.tensor(data=data.to_numpy(), dtype=torch.float32)
x = data[:, :2]
y = data[:, -1]

plt.scatter(x=class_0[:, 0], y=class_0[:, 1], label='class 0')
plt.scatter(x=class_1[:, 0], y=class_1[:, 1], label='class 1')
plt.legend()
plt.xlabel('$x_1$')
plt.ylabel('$x_2$')
plt.xlim(-1.1, 3.1)
plt.ylim(-32, 42)
plt.tight_layout()
------------------


[0;31m---------------------------------------------------------------------------[0m
[0;31mNameError[0m                                 Traceback (most recent call last)
Cell [0;32mIn[5], line 5[0m
[1;32m      3[0m class_0 [38;5;241m=[39m data[data[[38;5;124m'[39m[38;5;124my[39m[38;5;124m'[39m] [38;5;241m==[39m [38;5;241m0[39m][[[38;5;124m'[39m[38;5;124mx_1[39m[38;5;124m'[39m, [38;5;124m'[39m[38;5;124mx_2[39m[38;5;124m'[39m]]
[1;32m      4[0m class_1 [38;5;241m=[39m data[data[[38;5;124m'[39m[38;5;124my[39m[38;5;124m'[39m] [38;5;241m==[39m [38;5;241m1[39m][[[38;5;124m'[39m[38;5;124mx_1[39m[38;5;124m'[39m, [38;5;124m'[39m[38;5;124mx_2[39m[38;5;124m'[39m]]
[0;32m----> 5[0m class_0 [38;5;241m=[39m [43mtorch[49m[38;5;241m.[39mtensor(data[38;5;241m=[39mclass_0[38;5;241m.[39mto_numpy(), dtype[38;5;241m=[39mtorch[38;5;241m.[39mfloat32)
[1;32m      6[0m class_1 [38;5;241m=[39m torch[38;5;241m.[39mtensor(data[38;5;241m=[39mclass_1[38;5;241m.[39mto_numpy(), dtype[38;5;241m=[39mtorch[38;5;241m.[39mfloat32)
[1;32m      7[0m data [38;5;241m=[39m torch[38;5;241m.[39mtensor(data[38;5;241m=[39mdata[38;5;241m.[39mto_numpy(), dtype[38;5;241m=[39mtorch[38;5;241m.[39mfloat32)

[0;31mNameError[0m: name 'torch' is not defined

